<mujoco model="go2">
  <compiler angle="radian" meshdir="assets" autolimits="true" />

  <option timestep="0.002" cone="elliptic" impratio="100" solver="Newton" iterations="50" />

  <default>
    <default class="go2">
      <geom friction="0.6" margin="0.001" condim="1" />
      <joint axis="0 1 0" damping="0.5" armature="0.01" frictionloss="0.2" />
      
      <default class="haa_joint">
        <joint axis="1 0 0" range="-1.0472 1.0472" />
      </default>
      <default class="hfe_joint">
        <joint range="-1.5708 3.4907" />
      </default>
      <default class="kfe_joint">
        <joint range="-2.7227 -0.83776" />
      </default>

      <default class="visual">
        <geom type="mesh" contype="0" conaffinity="0" group="2" />
      </default>
      <default class="collision">
        <geom group="3" />
        <default class="foot">
          <geom type="sphere" size="0.022" pos="0 0 -0.213" priority="1" condim="6" friction="0.8 0.02 0.01" />
        </default>
      </default>
    </default>
  </default>

  <asset>
    <material name="metal" rgba=".9 .95 .95 1" />
    <material name="black" rgba="0 0 0 1" />
    <material name="white" rgba="1 1 1 1" />
    <material name="gray" rgba="0.671705 0.692426 0.774270 1" />

    <mesh file="base_0.obj" />
    <mesh file="base_1.obj" />
    <mesh file="base_2.obj" />
    <mesh file="base_3.obj" />
    <mesh file="base_4.obj" />
    <mesh file="hip_0.obj" />
    <mesh file="hip_1.obj" />
    <mesh file="thigh_0.obj" />
    <mesh file="thigh_1.obj" />
    <mesh file="thigh_mirror_0.obj" />
    <mesh file="thigh_mirror_1.obj" />
    <mesh file="calf_0.obj" />
    <mesh file="calf_1.obj" />
    <mesh file="calf_mirror_0.obj" />
    <mesh file="calf_mirror_1.obj" />
    <mesh file="foot.obj" />
  </asset>

  <worldbody>
    <body name="base" pos="0 0 0.445" childclass="go2">
      <inertial pos="0.021112 0 -0.005366" quat="-0.000543471 0.713435 -0.00173769 0.700719"
        mass="6.921" diaginertia="0.107027 0.0980771 0.0244531" />
      <freejoint name="root" />
      
      <geom mesh="base_0" material="black" class="visual" />
      <geom mesh="base_1" material="black" class="visual" />
      <geom mesh="base_2" material="black" class="visual" />
      <geom mesh="base_3" material="white" class="visual" />
      <geom mesh="base_4" material="gray" class="visual" />
      
      <geom size="0.1881 0.04675 0.057" type="box" class="collision" />
      <geom size="0.05 0.045" pos="0.285 0 0.01" type="cylinder" class="collision" />
      <geom size="0.047" pos="0.293 0 -0.06" class="collision" />
      
      <site name="imu" pos="-0.02557 0 0.04232" />

      <body name="RF_HIP" pos="0.1934 -0.0465 0">
        <inertial pos="-0.0054 -0.00194 -0.000105" quat="0.498237 0.505462 0.499245 0.497014" mass="0.678" diaginertia="0.00088403 0.000596003 0.000479967" />
        <joint name="RF_HAA" class="haa_joint" />
        <geom mesh="hip_0" material="metal" class="visual" quat="0 1 0 0" />
        <geom mesh="hip_1" material="gray" class="visual" quat="0 1 0 0" />
        <geom size="0.046 0.02" pos="0 -0.08 0" quat="0.707107 0.707107 0 0" type="cylinder" class="collision" />
        <body name="RF_THIGH" pos="0 -0.0955 0">
          <inertial pos="-0.00374 0.0223 -0.0327" quat="0.551623 -0.0200632 0.0847635 0.829533" mass="1.152" diaginertia="0.00594973 0.00584149 0.000878787" />
          <joint name="RF_HFE" class="hfe_joint" />
          <geom mesh="thigh_mirror_0" material="metal" class="visual" />
          <geom mesh="thigh_mirror_1" material="gray" class="visual" />
          <geom size="0.1065 0.01225 0.017" pos="0 0 -0.1065" quat="0.707107 0 0.707107 0" type="box" class="collision" />
          <body name="RF_SHANK" pos="0 0 -0.213">
            <inertial pos="0.00629595 0.000622121 -0.141417" quat="0.703508 -0.00450087 0.00154099 0.710672" mass="0.241352" diaginertia="0.0014901 0.00146356 5.31397e-05" />
            <joint name="RF_KFE" class="kfe_joint" />
            <geom mesh="calf_mirror_0" material="gray" class="visual" />
            <geom mesh="calf_mirror_1" material="black" class="visual" />
            <geom name="RF_FOOT" class="foot" />
            <site name="RF" pos="0 0 -0.213" type="sphere" size="0.023" group="5" />
          </body>
        </body>
      </body>

      <body name="LF_HIP" pos="0.1934 0.0465 0">
        <inertial pos="-0.0054 0.00194 -0.000105" quat="0.497014 0.499245 0.505462 0.498237" mass="0.678" diaginertia="0.00088403 0.000596003 0.000479967" />
        <joint name="LF_HAA" class="haa_joint" />
        <geom mesh="hip_0" material="metal" class="visual" />
        <geom mesh="hip_1" material="gray" class="visual" />
        <geom size="0.046 0.02" pos="0 0.08 0" quat="1 1 0 0" type="cylinder" class="collision" />
        <body name="LF_THIGH" pos="0 0.0955 0">
          <inertial pos="-0.00374 -0.0223 -0.0327" quat="0.829533 0.0847635 -0.0200632 0.551623" mass="1.152" diaginertia="0.00594973 0.00584149 0.000878787" />
          <joint name="LF_HFE" class="hfe_joint" />
          <geom mesh="thigh_0" material="metal" class="visual" />
          <geom mesh="thigh_1" material="gray" class="visual" />
          <geom size="0.1065 0.01225 0.017" pos="0 0 -0.1065" quat="0.707107 0 0.707107 0" type="box" class="collision" />
          <body name="LF_SHANK" pos="0 0 -0.213">
            <inertial pos="0.00629595 -0.000622121 -0.141417" quat="0.710672 0.00154099 -0.00450087 0.703508" mass="0.241352" diaginertia="0.0014901 0.00146356 5.31397e-05" />
            <joint name="LF_KFE" class="kfe_joint" />
            <geom mesh="calf_0" material="gray" class="visual" />
            <geom mesh="calf_1" material="black" class="visual" />
            <geom name="LF_FOOT" class="foot" />
            <site name="LF" pos="0 0 -0.213" type="sphere" size="0.023" group="5" />
          </body>
        </body>
      </body>

      <body name="RH_HIP" pos="-0.1934 -0.0465 0">
        <inertial pos="0.0054 -0.00194 -0.000105" quat="0.499245 0.497014 0.498237 0.505462" mass="0.678" diaginertia="0.00088403 0.000596003 0.000479967" />
        <joint name="RH_HAA" class="haa_joint" />
        <geom mesh="hip_0" material="metal" class="visual" quat="0 0 0 1" />
        <geom mesh="hip_1" material="gray" class="visual" quat="0 0 0 1" />
        <geom size="0.046 0.02" pos="0 -0.08 0" quat="0.707107 0.707107 0 0" type="cylinder" class="collision" />
        <body name="RH_THIGH" pos="0 -0.0955 0">
          <inertial pos="-0.00374 0.0223 -0.0327" quat="0.551623 -0.0200632 0.0847635 0.829533" mass="1.152" diaginertia="0.00594973 0.00584149 0.000878787" />
          <joint name="RH_HFE" class="hfe_joint" />
          <geom mesh="thigh_mirror_0" material="metal" class="visual" />
          <geom mesh="thigh_mirror_1" material="gray" class="visual" />
          <geom size="0.1065 0.01225 0.017" pos="0 0 -0.1065" quat="0.707107 0 0.707107 0" type="box" class="collision" />
          <body name="RH_SHANK" pos="0 0 -0.213">
            <inertial pos="0.00629595 0.000622121 -0.141417" quat="0.703508 -0.00450087 0.00154099 0.710672" mass="0.241352" diaginertia="0.0014901 0.00146356 5.31397e-05" />
            <joint name="RH_KFE" class="kfe_joint" />
            <geom mesh="calf_mirror_0" material="gray" class="visual" />
            <geom mesh="calf_mirror_1" material="black" class="visual" />
            <geom name="RH_FOOT" class="foot" />
            <site name="RH" pos="0 0 -0.213" type="sphere" size="0.023" group="5" />
          </body>
        </body>
      </body>

      <body name="LH_HIP" pos="-0.1934 0.0465 0">
        <inertial pos="0.0054 0.00194 -0.000105" quat="0.505462 0.498237 0.497014 0.499245" mass="0.678" diaginertia="0.00088403 0.000596003 0.000479967" />
        <joint name="LH_HAA" class="haa_joint" />
        <geom mesh="hip_0" material="metal" class="visual" quat="0 0 1 0" />
        <geom mesh="hip_1" material="gray" class="visual" quat="0 0 1 0" />
        <geom size="0.046 0.02" pos="0 0.08 0" quat="0.707107 0.707107 0 0" type="cylinder" class="collision" />
        <body name="LH_THIGH" pos="0 0.0955 0">
          <inertial pos="-0.00374 -0.0223 -0.0327" quat="0.829533 0.0847635 -0.0200632 0.551623" mass="1.152" diaginertia="0.00594973 0.00584149 0.000878787" />
          <joint name="LH_HFE" class="hfe_joint" />
          <geom mesh="thigh_0" material="metal" class="visual" />
          <geom mesh="thigh_1" material="gray" class="visual" />
          <geom size="0.1065 0.01225 0.017" pos="0 0 -0.1065" quat="0.707107 0 0.707107 0" type="box" class="collision" />
          <body name="LH_SHANK" pos="0 0 -0.213">
            <inertial pos="0.00629595 -0.000622121 -0.141417" quat="0.710672 0.00154099 -0.00450087 0.703508" mass="0.241352" diaginertia="0.0014901 0.00146356 5.31397e-05" />
            <joint name="LH_KFE" class="kfe_joint" />
            <geom mesh="calf_0" material="gray" class="visual" />
            <geom mesh="calf_1" material="black" class="visual" />
            <geom name="LH_FOOT" class="foot" />
            <site name="LH" pos="0 0 -0.213" type="sphere" size="0.023" group="5" />
          </body>
        </body>
      </body>
    </body>
  </worldbody>

  <contact>
    <exclude body1="base" body2="LF_THIGH" />
    <exclude body1="base" body2="RF_THIGH" />
    <exclude body1="base" body2="LH_THIGH" />
    <exclude body1="base" body2="RH_THIGH" />
  </contact>

  <actuator>
    <motor name="LF_HAA" joint="LF_HAA" ctrllimited="true" ctrlrange="-23.7 23.7" />
    <motor name="LF_HFE" joint="LF_HFE" ctrllimited="true" ctrlrange="-23.7 23.7" />
    <motor name="LF_KFE" joint="LF_KFE" ctrllimited="true" ctrlrange="-45.43 45.43" />
    <motor name="RF_HAA" joint="RF_HAA" ctrllimited="true" ctrlrange="-23.7 23.7" />
    <motor name="RF_HFE" joint="RF_HFE" ctrllimited="true" ctrlrange="-23.7 23.7" />
    <motor name="RF_KFE" joint="RF_KFE" ctrllimited="true" ctrlrange="-45.43 45.43" />
    <motor name="LH_HAA" joint="LH_HAA" ctrllimited="true" ctrlrange="-23.7 23.7" />
    <motor name="LH_HFE" joint="LH_HFE" ctrllimited="true" ctrlrange="-23.7 23.7" />
    <motor name="LH_KFE" joint="LH_KFE" ctrllimited="true" ctrlrange="-45.43 45.43" />
    <motor name="RH_HAA" joint="RH_HAA" ctrllimited="true" ctrlrange="-23.7 23.7" />
    <motor name="RH_HFE" joint="RH_HFE" ctrllimited="true" ctrlrange="-23.7 23.7" />
    <motor name="RH_KFE" joint="RH_KFE" ctrllimited="true" ctrlrange="-45.43 45.43" />
  </actuator>

  <sensor>
    <framequat name="orientation" objtype="site" objname="imu" />
    <gyro name="angular-velocity" site="imu" />
    <accelerometer name="linear-acceleration" site="imu" />
    <framepos name="position" objtype="site" objname="imu" />
    <framelinvel name="linear-velocity" objtype="site" objname="imu" />

    <jointpos name="LF_HAA_pos" joint="LF_HAA" />
    <jointpos name="LF_HFE_pos" joint="LF_HFE" />
    <jointpos name="LF_KFE_pos" joint="LF_KFE" />
    <jointpos name="RF_HAA_pos" joint="RF_HAA" />
    <jointpos name="RF_HFE_pos" joint="RF_HFE" />
    <jointpos name="RF_KFE_pos" joint="RF_KFE" />
    <jointpos name="LH_HAA_pos" joint="LH_HAA" />
    <jointpos name="LH_HFE_pos" joint="LH_HFE" />
    <jointpos name="LH_KFE_pos" joint="LH_KFE" />
    <jointpos name="RH_HAA_pos" joint="RH_HAA" />
    <jointpos name="RH_HFE_pos" joint="RH_HFE" />
    <jointpos name="RH_KFE_pos" joint="RH_KFE" />
  </sensor>

  <keyframe>
    <key name="home" qpos="0 0 0.35 1 0 0 0 0 0.9 -1.8 0 0.9 -1.8 0 0.9 -1.8 0 0.9 -1.8"
      ctrl="0 0 0 0 0 0 0 0 0 0 0 0" />
  </keyframe>
</mujoco>