<mujoco model="go1">
  <compiler angle="radian" meshdir="assets" autolimits="true"/>

  <option timestep="0.001" cone="elliptic" impratio="100" solver="Newton" iterations="50"/>

  <default>
    <default class="go1">
      <geom friction="0.6" margin="0.001" condim="1"/>
      <joint axis="0 1 0" damping="0.5" armature="0.01" frictionloss="0.2"/>
      
      <default class="haa_joint">
        <joint axis="1 0 0" range="-0.863 0.863"/>
      </default>
      <default class="hfe_joint">
        <joint range="-0.686 4.501"/>
      </default>
      <default class="kfe_joint">
        <joint range="-2.818 -0.888"/>
      </default>
      
      <default class="visual">
        <geom type="mesh" contype="0" conaffinity="0" group="2" material="dark"/>
      </default>
      <default class="collision">
        <geom group="3" type="capsule"/>
        <default class="hip_left1">
          <geom size="0.046 0.02" pos="0 0.045 0" quat="1 1 0 0" type="cylinder"/>
        </default>
        <default class="hip_left2">
          <geom size="0.031 0.02" pos="0 0.065 0" quat="1 1 0 0" type="cylinder"/>
        </default>
        <default class="hip_left3">
          <geom size="0.046 0.02" quat="1 1 0 0" type="cylinder"/>
        </default>
        <default class="hip_right1">
          <geom size="0.046 0.02" pos="0 -0.045 0" quat="1 1 0 0" type="cylinder"/>
        </default>
        <default class="hip_right2">
          <geom size="0.031 0.02" pos="0 -0.065 0" quat="1 1 0 0" type="cylinder"/>
        </default>
        <default class="hip_right3">
          <geom size="0.046 0.02" quat="1 1 0 0" type="cylinder"/>
        </default>
        <default class="thigh1">
          <geom size="0.015" fromto="-0.02 0 0 -0.02 0 -0.16"/>
        </default>
        <default class="thigh2">
          <geom size="0.015" fromto="0 0 0 -0.02 0 -0.1"/>
        </default>
        <default class="thigh3">
          <geom size="0.015" fromto="-0.02 0 -0.16 0 0 -0.2"/>
        </default>
        <default class="calf1">
          <geom size="0.01" fromto="0 0 0 0.02 0 -0.13"/>
        </default>
        <default class="calf2">
          <geom size="0.01" fromto="0.02 0 -0.13 0 0 -0.2"/>
        </default>
        <default class="foot">
          <geom type="sphere" size="0.023" pos="0 0 -0.213" priority="1" solimp="0.015 1 0.023" condim="6"
            friction="0.8 0.02 0.01"/>
        </default>
      </default>
    </default>
  </default>

  <asset>
    <material name="dark" rgba="0.2 0.2 0.2 1"/>
    <mesh class="go1" file="trunk.stl"/>
    <mesh class="go1" file="hip.stl"/>
    <mesh class="go1" file="thigh_mirror.stl"/>
    <mesh class="go1" file="calf.stl"/>
    <mesh class="go1" file="thigh.stl"/>
  </asset>

  <worldbody>
    <light name="spotlight" mode="targetbodycom" target="base" pos="0 -1 2"/>
    <body name="base" pos="0 0 0.445" childclass="go1">
      <camera name="tracking" mode="trackcom" pos="0 -1 0.8" xyaxes="1 0 0 0 1 1"/>
      <site name="head" pos="0.3 0 0" rgba="1 0 0 1" size="0.02" group="5"/>
      <inertial pos="0.0223 0.002 -0.0005" quat="-0.00342088 0.705204 0.000106698 0.708996" mass="5.204"
        diaginertia="0.0716565 0.0630105 0.0168101"/>
      <freejoint/>
      <geom class="visual" mesh="trunk"/>
      <geom class="collision" size="0.125 0.04 0.057" type="box"/>
      <geom class="collision" quat="1 0 1 0" pos="0 -0.04 0" size="0.058 0.125" type="cylinder"/>
      <geom class="collision" quat="1 0 1 0" pos="0 +0.04 0" size="0.058 0.125" type="cylinder"/>
      <geom class="collision" pos="0.25 0 0" size="0.005 0.06 0.05" type="box"/>
      <geom class="collision" pos="0.25 0.06 -0.01" size="0.009 0.035"/>
      <geom class="collision" pos="0.25 -0.06 -0.01" size="0.009 0.035"/>
      <geom class="collision" pos="0.25 0 -0.05" size="0.01 0.06" quat="1 1 0 0"/>
      <geom class="collision" pos="0.255 0 0.0355" size="0.021 0.052" quat="1 1 0 0"/>
      <site name="imu" pos="0 0 0"/>

      <body name="RF_HIP" pos="0.1881 -0.04675 0">
        <inertial pos="-0.0049166 0.00762615 -8.865e-05" quat="0.507341 0.514169 0.495027 0.482891" mass="0.68"
          diaginertia="0.000734064 0.000468438 0.000398719"/>
        <joint class="haa_joint" name="RF_HAA"/>
        <geom class="visual" mesh="hip" quat="1 0 0 0"/>
        <geom class="hip_right1"/>
        <geom class="hip_right2"/>
        <body name="RF_THIGH" pos="0 -0.08 0">
          <inertial pos="-0.00304722 0.019315 -0.0305004" quat="0.65243 -0.0272313 0.0775126 0.753383" mass="1.009"
            diaginertia="0.00478717 0.00460903 0.000709268"/>
          <joint class="hfe_joint" name="RF_HFE"/>
          <geom class="visual" mesh="thigh_mirror"/>
          <geom class="thigh1"/>
          <geom class="thigh2"/>
          <geom class="thigh3"/>
          <body name="RF_SHANK" pos="0 0 -0.213">
            <inertial pos="0.00429862 0.000976676 -0.146197" quat="0.691246 0.00357467 0.00511118 0.722592"
              mass="0.195862" diaginertia="0.00149767 0.00148468 3.58427e-05"/>
            <joint class="kfe_joint" name="RF_KFE"/>
            <geom class="visual" mesh="calf"/>
            <geom class="calf1"/>
            <geom class="calf2"/>
            <geom name="RF_FOOT" class="foot"/>
            <site name="RF" pos="0 0 -0.213" type="sphere" size="0.023" group="5"/>
          </body>
        </body>
      </body>

      <body name="LF_HIP" pos="0.1881 0.04675 0">
        <inertial pos="-0.0049166 -0.00762615 -8.865e-05" quat="0.482891 0.495027 0.514169 0.507341" mass="0.68"
          diaginertia="0.000734064 0.000468438 0.000398719"/>
        <joint class="haa_joint" name="LF_HAA"/>
        <geom class="visual" mesh="hip"/>
        <geom class="hip_left1"/>
        <geom class="hip_left2"/>
        <body name="LF_THIGH" pos="0 0.08 0">
          <inertial pos="-0.00304722 -0.019315 -0.0305004" quat="0.753383 0.0775126 -0.0272313 0.65243" mass="1.009"
            diaginertia="0.00478717 0.00460903 0.000709268"/>
          <joint class="hfe_joint" name="LF_HFE"/>
          <geom class="visual" mesh="thigh"/>
          <geom class="thigh1"/>
          <geom class="thigh2"/>
          <geom class="thigh3"/>
          <body name="LF_SHANK" pos="0 0 -0.213">
            <inertial pos="0.00429862 0.000976676 -0.146197" quat="0.691246 0.00357467 0.00511118 0.722592"
              mass="0.195862" diaginertia="0.00149767 0.00148468 3.58427e-05"/>
            <joint class="kfe_joint" name="LF_KFE"/>
            <geom class="visual" mesh="calf"/>
            <geom class="calf1"/>
            <geom class="calf2"/>
            <geom name="LF_FOOT" class="foot"/>
            <site name="LF" pos="0 0 -0.213" type="sphere" size="0.023" group="5"/>
          </body>
        </body>
      </body>

      <body name="RH_HIP" pos="-0.1881 -0.04675 0">
        <inertial pos="0.0049166 0.00762615 -8.865e-05" quat="0.495027 0.482891 0.507341 0.514169" mass="0.68"
          diaginertia="0.000734064 0.000468438 0.000398719"/>
        <joint class="haa_joint" name="RH_HAA"/>
        <geom class="visual" quat="0 0 0 -1" mesh="hip"/>
        <geom class="hip_right1"/>
        <geom class="hip_right2"/>
        <geom class="hip_right3"/>
        <body name="RH_THIGH" pos="0 -0.08 0">
          <inertial pos="-0.00304722 0.019315 -0.0305004" quat="0.65243 -0.0272313 0.0775126 0.753383" mass="1.009"
            diaginertia="0.00478717 0.00460903 0.000709268"/>
          <joint class="hfe_joint" name="RH_HFE"/>
          <geom class="visual" mesh="thigh_mirror"/>
          <geom class="thigh1"/>
          <geom class="thigh2"/>
          <geom class="thigh3"/>
          <body name="RH_SHANK" pos="0 0 -0.213">
            <inertial pos="0.00429862 0.000976676 -0.146197" quat="0.691246 0.00357467 0.00511118 0.722592"
              mass="0.195862" diaginertia="0.00149767 0.00148468 3.58427e-05"/>
            <joint class="kfe_joint" name="RH_KFE"/>
            <geom class="visual" mesh="calf"/>
            <geom class="calf1"/>
            <geom class="calf2"/>
            <geom name="RH_FOOT" class="foot"/>
            <site name="RH" pos="0 0 -0.213" type="sphere" size="0.023" group="5"/>
          </body>
        </body>
      </body>

      <body name="LH_HIP" pos="-0.1881 0.04675 0">
        <inertial pos="0.0049166 -0.00762615 -8.865e-05" quat="0.514169 0.507341 0.482891 0.495027" mass="0.68"
          diaginertia="0.000734064 0.000468438 0.000398719"/>
        <joint class="haa_joint" name="LH_HAA"/>
        <geom class="visual" quat="0 0 1 0" mesh="hip"/>
        <geom class="hip_left1"/>
        <geom class="hip_left2"/>
        <geom class="hip_left3"/>
        <body name="LH_THIGH" pos="0 0.08 0">
          <inertial pos="-0.00304722 -0.019315 -0.0305004" quat="0.753383 0.0775126 -0.0272313 0.65243" mass="1.009"
            diaginertia="0.00478717 0.00460903 0.000709268"/>
          <joint class="hfe_joint" name="LH_HFE"/>
          <geom class="visual" mesh="thigh"/>
          <geom class="thigh1"/>
          <geom class="thigh2"/>
          <geom class="thigh3"/>
          <body name="LH_SHANK" pos="0 0 -0.213">
            <inertial pos="0.00429862 0.000976676 -0.146197" quat="0.691246 0.00357467 0.00511118 0.722592"
              mass="0.195862" diaginertia="0.00149767 0.00148468 3.58427e-05"/>
            <joint class="kfe_joint" name="LH_KFE"/>
            <geom class="visual" mesh="calf"/>
            <geom class="calf1"/>
            <geom class="calf2"/>
            <geom name="LH_FOOT" class="foot"/>
            <site name="LH" pos="0 0 -0.213" type="sphere" size="0.023" group="5"/>
          </body>
        </body>
      </body>
    </body>
  </worldbody>

  <contact>
    <exclude body1="base" body2="LF_THIGH"/>
    <exclude body1="base" body2="RF_THIGH"/>
    <exclude body1="base" body2="LH_THIGH"/>
    <exclude body1="base" body2="RH_THIGH"/>
  </contact>

  <actuator>
    <motor name="LF_HAA" joint="LF_HAA" ctrllimited="true" ctrlrange="-23.7 23.7"/>
    <motor name="LF_HFE" joint="LF_HFE" ctrllimited="true" ctrlrange="-23.7 23.7"/>
    <motor name="LF_KFE" joint="LF_KFE" ctrllimited="true" ctrlrange="-35.55 35.55"/>
    
    <motor name="RF_HAA" joint="RF_HAA" ctrllimited="true" ctrlrange="-23.7 23.7"/>
    <motor name="RF_HFE" joint="RF_HFE" ctrllimited="true" ctrlrange="-23.7 23.7"/>
    <motor name="RF_KFE" joint="RF_KFE" ctrllimited="true" ctrlrange="-35.55 35.55"/>
    
    <motor name="LH_HAA" joint="LH_HAA" ctrllimited="true" ctrlrange="-23.7 23.7"/>
    <motor name="LH_HFE" joint="LH_HFE" ctrllimited="true" ctrlrange="-23.7 23.7"/>
    <motor name="LH_KFE" joint="LH_KFE" ctrllimited="true" ctrlrange="-35.55 35.55"/>
    
    <motor name="RH_HAA" joint="RH_HAA" ctrllimited="true" ctrlrange="-23.7 23.7"/>
    <motor name="RH_HFE" joint="RH_HFE" ctrllimited="true" ctrlrange="-23.7 23.7"/>
    <motor name="RH_KFE" joint="RH_KFE" ctrllimited="true" ctrlrange="-35.55 35.55"/>
  </actuator>

<keyframe>
    <key name="home" qpos="0 0 0.35 1 0 0 0 0.1 0.8 -1.5 -0.1 0.8 -1.5 0.1 1.0 -1.5 -0.1 1.0 -1.5"
      ctrl="0 0 0 0 0 0 0 0 0 0 0 0"/>
  </keyframe>
</mujoco>